<p align="left">
 <a href="05_15.md">◀ Back: Handler Error Boundaries.</a>
</p>

---
# Hide Console Error Logs.

En el [punto anterior](./05_15.md) hemos visto como escribir un test para uno de los componentes de React que está implementando el método `componentDidCatch` y como tal será capaz de capturar todos los errores que se produzcan dentro del mismo sin que se la aplicación deje de funcionar logrando tratarlo de la forma correcta (es lo que se conoce como un **Error Boundary**). 

Sin embargo también hemos visto como tras la ejecución de nuestro último test pese a que este pasa correctamente en la consola se nos muestra la información del error que se ha producido como consecuencia de que pese a que el componente no dejará de fallar React lo que hace es escribir la información del error (el mensaje asociado y el estado de la pila) por la consola:

```bash
$ npm run test

 PASS  src/react/__tests__/error-bounday-01.js
  ✓ calls reportError and renders that there was a problem (64 ms)

  console.error
    Error: Uncaught [Error: Boom]
    [...]
  console.error
    The above error occurred in the <Bomb> component:
```

Pero si analizamos más detenidamente las veces que aparece el mensaje de error veremos que son dos siendo la primera de ellas como cosecuencia de que durante la ejecución del código del test efectivamente se está lanzando un error y por lo tanto Jest así lo muestra por la consola y la segunda tiene que ver con React (más concretamente por ReactDOM) ya que el mensaje que nos muestra tiene asociado la jerarquía de componentes que están involucrados cuando se produce el error.

¿Qué podemos hacer para evitar estos mensajes de error en la consola? Pues teniendo en cuenta que lo que vamos a probar es precisamente si se produce el error o no y en ningún caso nos va a interesar que la información del error se nos muestre por la consola, lo que podemos hacer es *mockear* el método `error` del objeto `console` dejando que el resto de métodos para este objeto sigan funcionando como deberían hacerlo lo que se traduce en que vamos a tener que hacer uso del método `spyOn` del objeto `jest` únicamente para ese método de ese objeto.

Y no solamente eso, sino que como además queremos que este sea el comportamiento para todos los test vamos a hacer uso de la función global `beforeAll` de Jest para que *mock* se produzca ante de la ejecución de todos los test contenidos en el archivo y solamente una vez. Es decir, que escribiremos:

```js
beforeAll(() => {
  jest.spyOn(console, 'error').mockImplementation(() => {})
})
```

De esta manera durante la ejecución de nuestros test cuando se invoque a la función `error` del objeto `console` se estará ejecutando realmente a la función que hemos pasado como parametro al método `mockImplementation` que está asociada al objeto que retorna el método `spyOn` del objeto `jest` y que en nuestro caso lo que va a hacer es llamar a una función que no realizará nada. Por lo tanto, si ahora volvemos a ejecutar nuestro test veremos que en la consola solamente se nos estará informando de que este habrá pasado sin problemas sin mostar ningún mensaje de error:

```bash
$ npm run test

 PASS  src/react/__tests__/error-bounday-01.js
  ✓ calls reportError and renders that there was a problem (40 ms)
```

El problema con esta implementación es que si en algún momento se produce un error que sí que debería aparecer por la consola no vamos a verlo y por lo tanto no sabremos que algo que ha ido mal ha ocurrido en nuestro aplicación. En nuestro ejemplo en el código del componente `Bomb` podríamos tener algo como lo siguiente:

```js
function Bomb({ shouldThrow }) {
  if (shouldThrow) {
    console.error('really really bad do not miss this message')
    throw new Error('Boom')
  } else {
    return null
  }
}
```

Sin embargo pese a ello tras la ejecución de nuestro test al haber *mockeado* el método `error` como lo hemos hecho este mensaje no va a aparecer por la consola. ¿Qué podemos hacer para solucionar esto? Pues podemos, por ejemplo, basarnos en la explicación que hemos realizado anteriormente en lo relativo al número de veces que se llama a método `error` del objeto `console` y así crear una aserción sobre el mock sabiendo que, si todo va bien, el número de veces que se habría de llamar a este método sería dos (uno por Jest y otro por React) lo que nos llevaría a escribir la siguiente aserción:

```js
expect(console.error).toHaveBeenCalledTimes(2)
```

De hecho, si ahora volvemos a ejecutar nuestro test con el mensaje de error importante que no se debería perder en la consola nos aparecería algo como lo siguiente:

```bash
$ npm run test

 FAIL  src/react/__tests__/error-bounday-01.js
  ✕ calls reportError and renders that there was a problem (38 ms)

  ● calls reportError and renders that there was a problem

    expect(jest.fn()).toHaveBeenCalledTimes(expected)

    Expected number of calls: 2
    Received number of calls: 4
```

Es decir, que nuestro test falla porque el método `error` del objeto `console` es llamado más veces de las que esperábamos. Es más si quitamos el mensaje de error que hemos forzado dentro del componente `Bomb` ahora el test pasará sin problemas cuando es ejecutado:

```bash
$ npm run test

 PASS  src/react/__tests__/error-bounday-01.js
  ✓ calls reportError and renders that there was a problem (41 ms)
```

Nos quedará por quitar el mock sobre el método `error` del objeto console una vez finaliza la ejecución de todos los test que están contenidos dentro de nuestro archivo cosa que vamos a lograr gracias al uso de la invocación de la función `afterAll` que nos ofrece Jest donde dentro de la misma invocaremos al método `mockRestore` que nos proporciona el objeto mock.

```js
afterAll(() => {
  console.error.mockRestore()
})
```

De hecho si tras invocar a `mockRestore` escribirmos un mensaje de error por la consola tal y como sigue:

```js
afterAll(() => {
  console.error.mockRestore()
  console.error('hi')
})
```

Si ahora ejecutamos nuestro test veremos cómo perfectamente este mensaje aparecerá en la información que se muestra en la terminal:

```bash
$ npm run test

 PASS  src/react/__tests__/error-bounday-01.js
  ✓ calls reportError and renders that there was a problem (37 ms)

  console.error
    hi
```

Y no solamente eso, sino que tenemos que entender que en la implementación de nuestro test hemos estado haciendo uso de la función `afterEach` y dentro de la misma hemos llamado al método `clearAllMocks` que nos ofrece el objeto Jest:

```js
afterEach(() => {
  jest.clearAllMocks()
})
```

lo que viene a hacer que todos los contadores e información asociada a la invocación de nuestros mocks durante los test es borrada después de la ejecución de cada uno de ellos, lo que, para el caso que nos preocupa, nos vendrá a decir que el número de veces que es llamada se restaura a cero tras la ejecución de cada uno de los test pudiendo nuevamente volver a realizar las aserciones que consideremos oportunas tras cada una de las llamadas.

A continuación recogemos el código completo del test con el que hemos estado trabajando para tenerlo en un único lugar en el caso de que deba ser consultado:

```js
import '@testing-library/jest-dom/extend-expect'
import React from 'react'
import { render, fireEvent } from '@testing-library/react'
import { ErrorBoundary } from '../error-boundary'
import { reportError as mockReportError } from '../api'

jest.mock('../api')

beforeAll(() => {
  jest.spyOn(console, 'error').mockImplementation(() => {})
})

afterAll(() => {
  console.error.mockRestore()
})

afterEach(() => {
  jest.clearAllMocks()
})

function Bomb({ shouldThrow }) {
  if (shouldThrow) {
    throw new Error('Boom')
  } else {
    return null
  }
}

test('calls reportError and renders that there was a problem', () => {
  mockReportError.mockResolvedValueOnce({ success: true })
  const { rerender } = render(
    <ErrorBoundary>
      <Bomb />
    </ErrorBoundary>
  )
  rerender(
    <ErrorBoundary>
      <Bomb shouldThrow={true} />
    </ErrorBoundary>
  )

  const error = expect.any(Error)
  const info = { componentStack: expect.stringContaining('Bomb') }
  expect(mockReportError).toHaveBeenCalledWith(error, info)
  expect(mockReportError).toHaveBeenCalledTimes(1)
  expect(console.error).toHaveBeenCalledTimes(2)
})
```

---

<p align="right">
 <a href="05_17.md">Next: Ensure Error Boundaries Can Successfully Recover from Errors ▶</a>
</p>
