<p align="left">
 <a href="05_16.md">◀ Back: Hide Console Error Logs.</a>
</p>

---
# Ensure Error Boundaries Can Successfully Recover from Errors.

Mostramos a continuación el código del componente de React que nos servía para recoger la información un mensaje de error que se mostraba al usuario y que hemos estado probando en los puntos anteriores:

```js
import React from 'react'
import { reportError } from './api'

class ErrorBoundary extends React.Component {
  state = { hasError: false }

  componentDidCatch(error, info) {
    this.setState({ hasError: true })
    reportError(error, info)
  }

  tryAgain = () => this.setState({ hasError: false })

  render() {
    return this.state.hasError ? (
      <div>
        <div role='alert'>There were a problem.</div>{' '}
        <button onClick={ this.tryAgain }>Try again?</button>
      </div>
    ) : (
      this.props.children
    )
  }
}

export { ErrorBoundary }
```

Hasta ahora lo que hemos probado con nuestros test es que cuando se produce un error este es capturado por nuestro componente y, al tratarse de una **Error Boundary** de React (tiene implementado el método `componentDidCatch`) el código continúa su ejecución sin problemas pero nos falta por probar que una vez que se muestra el mensaje de error si el usuario pulsa sobre el botón que se renderiza en la interfaz la aplicación deja de mostrar el mensaje de error.

¿Cómo podemos hacer esto? Pues son muchas las formas que podríamos utilizar pero en nuestro caso vamos a seguir trabajando sobre el test que hemos estado desarrollando y lo que vamos a hacer es que una vez que realizamos las aserciones que tienen que ver con el hecho de que se haya producido un error vamos a volver a llamar a la función `rerender` para volver a mostrar nuestro componente pero esta vez sin ningún tipo de mensaje de error:

```js
test('calls reportError and renders that there was a problem', () => {
  mockReportError.mockResolvedValueOnce({ success: true })
  const { rerender } = render(
    <ErrorBoundary>
      <Bomb />
    </ErrorBoundary>
  )
  rerender(
    <ErrorBoundary>
      <Bomb shouldThrow={true} />
    </ErrorBoundary>
  )

  const error = expect.any(Error)
  const info = { componentStack: expect.stringContaining('Bomb') }
  expect(mockReportError).toHaveBeenCalledWith(error, info)
  expect(mockReportError).toHaveBeenCalledTimes(1)
  expect(console.error).toHaveBeenCalledTimes(2)

  rerender(
    <ErrorBoundary>
      <Bomb />
    </ErrorBoundary>
  )
})
```

¿Qué es lo que está sucediendo ahora? Pues que con el primer `rerender` hemos provocado que se produzca un error (y lo hemos verificado) y cuando se produce el error en el código del componente se produce un cambio en el valor de una de las variables de estado del componente (la variable `hasError`) pero esto no provoca automáticamente un rerenderiza del componente (estamos en un test) lo que nos obliga a que nosotros tengamos que forzar este rerenderizado con la invocación de la función `rerender`.

Con esto lo que estamos logrando es que al usuario se le esté mostrando el mensaje de error por lo que vamos a tener que obtener el botón sobre el que pulsar y lanzar el evento de pulsación sobre el mismo:

```js
const { rerender, getByText } = render(
// ...
rerender(
  <ErrorBoundary>
    <Bomb />
  </ErrorBoundary>
)
fireEvent.click(getByText(/try again/i))
```

Hecho esto lo siguiente que tenemos que hacer son las aserciones en nuestro código. La primera de ellas tendrá que ver con que cuando se está pulsa sobre el botón en cuestión no se llamará al método de la api externa que hemos *mockeado* para registrar la información del error:

```js
expect(mockReportError).not.toHaveBeenCalled()
```

También, como consecuencia de que no se ha producido un error, tendríamos que comprobar que no se ha llamado al método `error` dentro del objeto `console`:

```js
expect(mockReportError).not.toHaveBeenCalled()
expect(console.error).not.toHaveBeenCalled()
```

Sin embargo si ahora guardamos nuestro test y lo volvemos a ejecutar desde la terminal del sistema nos vamos a encontrar con que falla:

```bash
$npm run test

 FAIL  src/react/__tests__/error-bounday-01.js
  ✕ calls reportError and renders that there was a problem (51 ms)

  ● calls reportError and renders that there was a problem

    expect(jest.fn()).not.toHaveBeenCalled()

    Expected number of calls: 0
    Received number of calls: 1
```

Pero ¿por qué? La razón la obtenemos viendo que código completo de nuestro test ya que previamente habremos hecho una misma aserción sobre el número de veces que se ha llamado al mock `mockReportError` donde hemos visto que efectivamente se ha llamado una vez:

```js
test('calls reportError and renders that there was a problem', () => {
  mockReportError.mockResolvedValueOnce({ success: true })
  const { rerender, getByText } = render(
    <ErrorBoundary>
      <Bomb />
    </ErrorBoundary>
  )
  rerender(
    <ErrorBoundary>
      <Bomb shouldThrow={true} />
    </ErrorBoundary>
  )

  const error = expect.any(Error)
  const info = { componentStack: expect.stringContaining('Bomb') }
  expect(mockReportError).toHaveBeenCalledWith(error, info)
  expect(mockReportError).toHaveBeenCalledTimes(1)
  expect(console.error).toHaveBeenCalledTimes(2)

  rerender(
    <ErrorBoundary>
      <Bomb />
    </ErrorBoundary>
  )
  fireEvent.click(getByText(/try again/i))
  expect(mockReportError).not.toHaveBeenCalled()
  expect(console.error).not.toHaveBeenCalled()
})
```

Esto nos viene a decir que antes de la invocación de la función `rerender` lo que deberíamos hacer sería limpiar estos mocks para que los contadores asociados vuelvan a estar a cero y esto lo logramos simplemente llamando al método `mockClear` que ambos nos ofrecen:

```js
console.error.mockClear()
mockReportError.mockClear()
rerender(
  <ErrorBoundary>
    <Bomb />
  </ErrorBoundary>
)
fireEvent.click(getByText(/try again/i))
expect(mockReportError).not.toHaveBeenCalled()
expect(console.error).not.toHaveBeenCalled()
```

Si ahora guardamos el test y lo volvemos a ejecutar en la terminal del sistema vamos a poder comprobar como este pasará sin problemas:

```bash
$ npm run test

 PASS  src/react/__tests__/error-bounday-01.js
  ✓ calls reportError and renders that there was a problem (50 ms)
```

>
> `mocksClear` lo que hace es dejar volver todos los contadores asociados a un mock a cero dejando la implementación del mock tal y como estaba.
>

Vamos a continuar perfeccionando nuestro test probando que, cuando se está mostrando un mensaje de error al usuario, el mensaje de error asociado es el que estábamos esperando. Para ello tenemos que fijarnos que en el marcado de nuestro componente este mensaje de error está recogido dentro de un elemento `div` como sigue:

```js
<div role='alert'>There were a problem.</div>{' '}
```

Basándonos en ello lo primero que vamos a hacer es quedarnos con la función `getByRole` que nos retorna el objeto asociado a la invocación de la función `render`:

```js
const { rerender, getByText, getByRole } = render(
  <ErrorBoundary>
    <Bomb />
  </ErrorBoundary>
)
```

y una vez la tenemos a nuestra disposición lo siguiente que vamos a hacer es obtener el elemento dentro de marcado de nuestro componente, acceder al texto que contiene (gracias a al acceso a la atributo `textContent`) y posteriormente hacer una aserción para que compare que dicho texto (en concreto el contenido como html) sea igual a un texto que le pasaremos como parámetro (cosa que lograremos gracias a la invocación del método `toMatchInlineSnapshot`). Es decir que la aserción que vamos a realizar es la siguiente:

```js
expect(getByRole('alert').textContent).toMatchInlineSnapshot(`"There were a problem."`)
```

Si ahora guardamos nuestro test y lo volvemos a ejecutar desde la terminal del sistema el resultado que vamos a obtener es precisamente el que estábamos esperando:

```bash
$ npm run test

 PASS  src/react/__tests__/error-bounday-01.js
  ✓ calls reportError and renders that there was a problem (87 ms)
```

Es más, gracias a que estamos haciendo uso de una snapshot nos va a ser muy sencillo comprobar que en el caso de que queramos cambiar el contenido de nuestro mensaje de error esto será también muy sencillo de conseguir realizar en el código de nuestros test y así que sea detectado rápidamente.

Y no solamente esto sino que además podemos completar el código de nuestro test para que cuando se produzca el evento de pulsar sobre el botón para ocultar el mensaje de error y además se vuelva a rerenderizar el componente asegurar que el mensaje de error no es mostrado al usuario, lo que supone, en primer lugar, quedarnos con el método `queryByRole` que nos ofrece el objeto retorna la función `render`:

```js
const { rerender, getByText, getByRole, queryByRole } = render(
  <ErrorBoundary>
    <Bomb />
  </ErrorBoundary>
)
```

Y ahora podemos hacer uso del mismo para realizar las aserciciones al finalizar nuestro test:

```js
fireEvent.click(getByText(/try again/i))
expect(mockReportError).not.toHaveBeenCalled()
expect(console.error).not.toHaveBeenCalled()
expect(queryByRole('alert')).not.toBeInTheDocument()
```

Con estos cambios si volvemos a guardar nuestro test y a ejecutarlo nos vamos a encontrar con que pasa correctamente tal y como esperábamos:

```bash
$ npm run test

 PASS  src/react/__tests__/error-bounday-01.js
  ✓ calls reportError and renders that there was a problem (87 ms)
```

Es más, vamos a perfeccionar el test un poco más verificando además que el botón no se muestra al usuario para lo que seguiremos la misma técnica que en el caso anterior pero en este caso haciendo uso del método `queryByText` que nos ofrece el objeto que retorna la función `render`:

```js
const { rerender, getByText, getByRole, queryByRole, queryByText } = render(
  <ErrorBoundary>
    <Bomb />
  </ErrorBoundary>
)
```

Y ahora ya podemos utilizarlo en el conjunto de las aserciones que estamos realizando a la finalización del test cuando estamos verificando que no se muestra el mensaje de error:

```js
fireEvent.click(getByText(/try again/i))
expect(mockReportError).not.toHaveBeenCalled()
expect(console.error).not.toHaveBeenCalled()
expect(queryByRole('alert')).not.toBeInTheDocument()
expect(queryByText(/try again/i)).not.toBeInTheDocument()
```

lo que hace que si volvemos a ejecutar nuestro test desde la terminal del sistema no se producirá ningún error como se puede ver a continuación:

```bash
$ npm run test

 PASS  src/react/__tests__/error-bounday-01.js
  ✓ calls reportError and renders that there was a problem (86 ms)
```

Con esto damos por cubiertos todos los casos de uso a los que nos tenemos que enfrentar cuando estamos trabajando con los **Error Boundaries** de React. A continuación mostramos el código completo del test que hemos desarrollado para tenerlo recogido en un único sitio y que sea fácil consularlo cuando así lo necesitemos:

```js
import '@testing-library/jest-dom/extend-expect'
import React from 'react'
import { render, fireEvent } from '@testing-library/react'
import { ErrorBoundary } from '../error-boundary'
import { reportError as mockReportError } from '../api'

jest.mock('../api')

beforeAll(() => {
  jest.spyOn(console, 'error').mockImplementation(() => {})
})

afterAll(() => {
  console.error.mockRestore()
})

afterEach(() => {
  jest.clearAllMocks()
})

function Bomb({ shouldThrow }) {
  if (shouldThrow) {
    throw new Error('Boom')
  } else {
    return null
  }
}

test('calls reportError and renders that there was a problem', () => {
  mockReportError.mockResolvedValueOnce({ success: true })
  const { rerender, getByText, getByRole, queryByRole, queryByText } = render(
    <ErrorBoundary>
      <Bomb />
    </ErrorBoundary>
  )
  rerender(
    <ErrorBoundary>
      <Bomb shouldThrow={true} />
    </ErrorBoundary>
  )

  const error = expect.any(Error)
  const info = { componentStack: expect.stringContaining('Bomb') }
  expect(mockReportError).toHaveBeenCalledWith(error, info)
  expect(mockReportError).toHaveBeenCalledTimes(1)
  expect(console.error).toHaveBeenCalledTimes(2)

  expect(getByRole('alert').textContent).toMatchInlineSnapshot(`"There were a problem."`)

  console.error.mockClear()
  mockReportError.mockClear()
  rerender(
    <ErrorBoundary>
      <Bomb />
    </ErrorBoundary>
  )
  fireEvent.click(getByText(/try again/i))
  expect(mockReportError).not.toHaveBeenCalled()
  expect(console.error).not.toHaveBeenCalled()
  expect(queryByRole('alert')).not.toBeInTheDocument()
  expect(queryByText(/try again/i)).not.toBeInTheDocument()
})
```

---

<p align="right">
 <a href="05_02.md">Next: Simplify Using `rerender` ▶</a>
</p>
