<p align="left">
 <a href="05_14.md">◀ Back: Mock React Transition Group.</a>
</p>

---
# Handler Error Boundaries.

Supongamos que tenemos un Class Component de React que está haciendo uso del método `componentDidCatch` dentro del ciclo de vida del mismo para capturar todos los errores que se puedan producir en su ejecuación y enviarlos a un servidor backend para que puedan ser tratados gracias a la función `reportError` que está recogida en el módulo `api`:

```js
import React from 'react'
import { reportError } from './api'

class ErrorBoundary extends React.Component {
  state = { hasError: false }

  componentDidCatch(error, info) {
    this.setState({ hasError: true })
    reportError(error, info)
  }

  tryAgain = () => this.setState({ hasError: false })

  render() {
    return this.state.hasError ? (
      <div>
        <div role='alert'>There were a problem.</div>{' '}
        <button onClick={ this.tryAgain }>Try again?</button>
      </div>
    ) : (
      this.props.children
    )
  }
}

export { ErrorBoundary }
```

---
**Nota:** la estrategia de lanzar un error y este transmitirlo a otro componente para que lo trate (en este caso el módulo `api` de la aplicación) es bastante común en el diseño de la arquitectura de nuestras aplicaciones tanto que se le conoce con el nombre de **Fire and Forget**.

---

Lo que a nosotros nos gustaría probar en nuestros test es que cuando se produce un error durante la ejecución del componente efectivamente se está llamando a la función `reportError` dentro del módulo `api` y además que se muestra el mensaje de error al usuario. Comenzaremos importando todo lo necesario para la implementación del test lo que incluirá React, las utilidades de **react-testing-library** además del componente que vamos a probar:

```js
import '@testing-library/jest-dom/extend-expect'
import React from 'react'
import { render, fireEvent } from '@testing-library/react'
import { ErrorBoundary } from '../error-boundary'
```

Hecho esto el siguiente paso va a consistir en definir nuestro test que básicamete que cuando se produce un error se muestra el mensaje que esperábamos además de llamar a la función del módulo `api` que recogerá la información del error:

```js
test('calls reportError and renders that there was a problem', () => {})
```

Lo que tenemos que pensar es que para provocar el error y así poder realizar nuestro test vamos a tener que hacer que el componente `ErrorBoundary` (componente que estamos provando) durante su ejecución realice alguna acción que provoque un error. Es por esto que vamos a crear un componente de React adicional para la realización del test (recordemos que un componente no es más que una función) que será el que se encargará de lanzar un error en función de una prop que reciba:

```js
function Bomb({ shouldThrow }) {
  if (shouldThrow) {
    throw new Error('Boom')
  } else {
    return null
  }
}
```

Volviendo a nuestro test ahora lo que vamos a hacer renderizar el componente `ErrorBoundary` junto con `Bomb` pero sin que lance un error de tal manera que vamos a poder testear que no se produce el error y por lo tanto no se llama al método `reportError` del módulo `api` además de que 


```js
test('calls reportError and renders that there was a problem', () => {
  const { rerender } = render(
    <ErrorBoundary>
      <Bomb />
    </ErrorBoundary>
  )
  rerender(
    <ErrorBoundary>
      <Bomb shouldThrow={true} />
    </ErrorBoundary>
  )
})
```

Si todo funciona como esperamos en el momento en el que se produce un error se llamará a la función `reportError` del módulo `api` y lo que nosotros no queremos es que se produzca dicha llamada de forma real por lo que tenemos que *mockearla*. Para lograrlo lo que hacemos será *mockear* el módulo completo `api` gracias a la llamada al método `mock` del objeto `jest`:

```js
jest.mock('../api')
```

Y si recordamos de las explicaciones que hemos dado hasta ahora al hacer uso de la invocación a este método tendremos a nuestra disposición una versión *mockeada* de todas las funciones que proporciona por lo que simplemente tendremos que importala en nuestro código y, además, se considera una buena práctica de programación el asignarle un alias para así garantizar que estamos ante una versión de la función que está *mockeada*:

```js
import '@testing-library/jest-dom/extend-expect'
import React from 'react'
import { render, fireEvent } from '@testing-library/react'
import { ErrorBoundary } from '../error-boundary'
import { reportError as mockReportError } from '../api'
```

En el código del test lo que vamos a tener que hacer es indicar qué es lo que queremos que retorne la versión *mockada* de la la función gracias a la invocación del método `mockResolvedValueOnce` en el que vamos a indicar que la llamada a dicha función va a retornar un objeto con un único atributo denominado `success` y cuyo valor es `true`:

```js
test('calls reportError and renders that there was a problem', () => {
  mockReportError.mockResolvedValueOnce({ success: true })
```

---
**Nota:** para la realización de nuestro test no es necesario tener en cuenta el valor que retorna la función que estamos *mockeando* pero se incluye un valor para de esta manera enfatizar que retorna un valor como resultado de la ejecución `mockResolvedValueOnce`.

---

Ahora que tenemos el esqueleto de nuestro test ya podemos comenzar a hacer las aserciones asociadas al mismo. En primer lugar vamos a comprobar que se está llamando a la función `reportError` de la API con los atributos que esta espera que, si vamos al código del componente que estamos probando son:

```js
reportError(error, info)
```

pero ¿cónde está los valores `error` e `info`? pues en nuestro caso, en el test, no los vamos a tener por lo que los establecemos como `null` y así podemos establecer la primera de las aserciciones como sigue:

```js
const error = null
const info = null
expect(mockReportError).toHaveBeenCalledWith(error, info)
```

Sin embargo si ejecutamos nuestro test como está hasta ahora en la terminal del sistema podremos ver que este fallará y además la causa del fallo:

```bash
$ npm run test

 FAIL  src/react/__tests__/error-bounday-01.js
  ✕ calls reportError and renders that there was a problem (49 ms)

  ● calls reportError and renders that there was a problem

    expect(jest.fn()).toHaveBeenCalledWith(...expected)

    Expected: null, null
    Received: [Error: Boom], {"componentStack": "
```

El problema aquí es que hemos definido las variables `error` e `info` como `null` cuando realmente no lo son pero tampoco podemos garantizar a ciencia cierta el contenidod de los mismos sobre todo en el caso de la variable `info` porque la pila de ejecución va a depender del equipo en el que está corriendo el test. ¿Qué es lo que podemos hacer? Pues utilizar lo que se conoce como **Asymetric Object** que son objetos de utilidad a la hora de realizar nuestros test porque servirán como una especie de cajón desastre en el que se caben todas las instancias de un determinado tipo. En nuestro caso, si queremos que la variable `error` pueda ser establecida con cualquier objeto `Error` escribiríamos algo como lo siguiente:

```js
const error = expect.any(Error)
```

y para el caso de la variable `info` lo que vamos a esperar es sea un objeto que contiene el atributo `componentStack` y que el valor de este atributo va a ser un string que ha de contener la cadena `Bomb` por lo que podemos escribir algo como lo siguiente:

```js
const info = { componentStack: expect.stringContaining('Bomb') }
```

Esto nos deja el test como se puede ver a continuación:

```js
test('calls reportError and renders that there was a problem', () => {
  mockReportError.mockResolvedValueOnce({ success: true })
  const { rerender } = render(
    <ErrorBoundary>
      <Bomb />
    </ErrorBoundary>
  )
  rerender(
    <ErrorBoundary>
      <Bomb shouldThrow={true} />
    </ErrorBoundary>
  )

  const error = expect.any(Error)
  const info = { componentStack: expect.stringContaining('Bomb') }
  expect(mockReportError).toHaveBeenCalledWith(error, info)
})
```

que si lo guardamos y lo pasamos a ejecutar desde la terminal del sistema nos vamos a encontrar con que ahora sí que pasa aunque se nos siguen mostrando una serie de errores de ejecución que pasaremos a solventar a continuación.

```bash
$ npm run test

 PASS  src/react/__tests__/error-bounday-01.js
  ✓ calls reportError and renders that there was a problem (51 ms)

  console.error
    Error: Uncaught [Error: Boom]
```

Añadimos una nueva aserción en la que verificaremos que la función `mockReportError` es llamada únicamente una vez durante todo el proceso de ejecución del test lo que nos permite completar el test de integración con dicha función:

```js
test('calls reportError and renders that there was a problem', () => {
  mockReportError.mockResolvedValueOnce({ success: true })
  const { rerender } = render(
    <ErrorBoundary>
      <Bomb />
    </ErrorBoundary>
  )
  rerender(
    <ErrorBoundary>
      <Bomb shouldThrow={true} />
    </ErrorBoundary>
  )

  const error = expect.any(Error)
  const info = { componentStack: expect.stringContaining('Bomb') }
  expect(mockReportError).toHaveBeenCalledWith(error, info)
  expect(mockReportError).toHaveBeenCalledTimes(1)
})
```

Vamos a añadir un nuevo elemento más en nuestro archivo con los test y es que tenemos que pensar que hemos estado *mockeando* un módulo completo de la aplicación por lo que, a no ser que hagamos algo al respecto, para el resto de test que se ejecuten después del que acabamo de escribir el comportamiento de la misma pasará a ser el que hemos definido. Esto quiere decir que es necesario eliminar dicho mock tras la ejecución de cada uno de nuestros test cosa que vamos a lograr gracias a la invocación de la función `afterEach` que nos propociona Jest de forma global y dentro de la misma llamaremos al método `clearAllMocks` que pone a nuestra disposición el objeto `jest` con este propósito:

```js
afterEach(() => {
  jest.clearAllMocks()
})
```

Nos queda alguna modificación más que realizar para que desaparezcan los mensajes de error que aparecen por la consola con la ejecución de este test pero es algo que dejamos para un punto posterior. Lo que si hacemos ahora es mostrar el código completo con el contenido del test que se está llevando a cabo:

```js
import '@testing-library/jest-dom/extend-expect'
import React from 'react'
import { render, fireEvent } from '@testing-library/react'
import { ErrorBoundary } from '../error-boundary'
import { reportError as mockReportError } from '../api'

jest.mock('../api')

afterEach(() => {
  jest.clearAllMocks()
})

function Bomb({ shouldThrow }) {
  if (shouldThrow) {
    throw new Error('Boom')
  } else {
    return null
  }
}

test('calls reportError and renders that there was a problem', () => {
  mockReportError.mockResolvedValueOnce({ success: true })
  const { rerender } = render(
    <ErrorBoundary>
      <Bomb />
    </ErrorBoundary>
  )
  rerender(
    <ErrorBoundary>
      <Bomb shouldThrow={true} />
    </ErrorBoundary>
  )

  const error = expect.any(Error)
  const info = { componentStack: expect.stringContaining('Bomb') }
  expect(mockReportError).toHaveBeenCalledWith(error, info)
  expect(mockReportError).toHaveBeenCalledTimes(1)
})
```

---
**Nota:** si durante la ejecución de los test nos estamos encontrando con un mensaje de error del tipo *Missing class properties transform.* quiere decir que precisaremos instalar **babel-plugin-transform-class-properties** para que entienda la definición directa de los atributos de la clase dentro del código.

```bash
$ npm install --save-dev babel-plugin-transform-class-properties
```

Y ahora modificamos nuestro fichero `.babelrc` para que en el atributo `plugings` se incluya el que acabamos de instalar, como se puede ver a continuación:

```js
plugins: ['@babel/plugin-proposal-class-properties']
```

---

<p align="right">
 <a href="05_16.md">Next: Console Error Logs ▶</a>
</p>
