<p align="left">
 <a href="05_17.md">◀ Back: Ensure Error Boundaries Can Successfully Recover from Errors.</a>
</p>

---
# Simplify Using `rerender`.

En el código del test que hemos desarrollado en el [punto anterior](./05_17.md) nos hemos encontrado con varias llamadas al método `render` y `rerender` de **react-testing-library** como podemos ver en el siguiente fragmento del mismo:

```js
const { rerender, getByText, getByRole, queryByRole, queryByText } = render(
  <ErrorBoundary>
    <Bomb />
  </ErrorBoundary>
)
rerender(
  <ErrorBoundary>
    <Bomb shouldThrow={true} />
  </ErrorBoundary>
)

// ...

rerender(
  <ErrorBoundary>
    <Bomb />
  </ErrorBoundary>
)
```

¿Qué podemos ver aquí? Pues que en las tres llamadas que hemos estado realizando realmente lo que cambia en el contenido del componente hijo del componente `ErrorBoundary` lo que hace que de alguna manera la envoltura (wrap) con este componente sea repetitivo. Para situaciones como la anterior el método `render` nos ofrece la posibilidad de utilizar su versión sobrecargada en la que como segundo parámetro recibe un objeto en el que se pueden recoger una serie de propiedades como atributos del mismo siendo una de ellas, `wrapper` donde le podemos asignar un componente de React con el que queremos que se envuelva siempre el contenido que se le ha pasado como primer parámetro. En nuestro ejemplo esto nos dejaría algo como lo siguiente:

```js
const { rerender, getByText, getByRole, queryByRole, queryByText } = render(
  <Bomb />,
  { wrapper: ErrorBoundary }
)
```

Y ahora podemos sustituir la invocación de las llamadas a la función `rerender` porque el resultado del mismo quedará envuelto con el component `ErrorBoundary` lo que nos dejará el siguiente código:

```js
const { rerender, getByText, getByRole, queryByRole, queryByText } = render(
  <Bomb />,
  { wrapper: ErrorBoundary }
)
rerender(<Bomb shouldThrow={true} />)

// ...

rerender(<Bomb />)
```

Y si guardamos el trabajo y volvemos a ejecutar nuestros test el resultado del mismo será igual que antes, es decir, que todos los test pasarán:

```bash
$ npm run test

 PASS  src/react/__tests__/error-bounday-01.js
  ✓ calls reportError and renders that there was a problem (89 ms)
```

El código completo del test con el que hemos estado trabajando tras realizar esta modificación es el que se muestra a continuación:

```js
import '@testing-library/jest-dom/extend-expect'
import React from 'react'
import { render, fireEvent } from '@testing-library/react'
import { ErrorBoundary } from '../error-boundary'
import { reportError as mockReportError } from '../api'

jest.mock('../api')

beforeAll(() => {
  jest.spyOn(console, 'error').mockImplementation(() => {})
})

afterAll(() => {
  console.error.mockRestore()
})

afterEach(() => {
  jest.clearAllMocks()
})

function Bomb({ shouldThrow }) {
  if (shouldThrow) {
    throw new Error('Boom')
  } else {
    return null
  }
}

test('calls reportError and renders that there was a problem', () => {
  mockReportError.mockResolvedValueOnce({ success: true })
  const { rerender, getByText, getByRole, queryByRole, queryByText } = render(<Bomb />, {
    wrapper: ErrorBoundary
  })
  rerender(<Bomb shouldThrow={true} />)

  const error = expect.any(Error)
  const info = { componentStack: expect.stringContaining('Bomb') }
  expect(mockReportError).toHaveBeenCalledWith(error, info)
  expect(mockReportError).toHaveBeenCalledTimes(1)
  expect(console.error).toHaveBeenCalledTimes(2)

  expect(getByRole('alert').textContent).toMatchInlineSnapshot(`"There were a problem."`)

  console.error.mockClear()
  mockReportError.mockClear()
  rerender(<Bomb />)
  fireEvent.click(getByText(/try again/i))
  expect(mockReportError).not.toHaveBeenCalled()
  expect(console.error).not.toHaveBeenCalled()
  expect(queryByRole('alert')).not.toBeInTheDocument()
  expect(queryByText(/try again/i)).not.toBeInTheDocument()
})
```

---

<p align="right">
 <a href="05_19.md">Next: Test Driven Development of a React Form ▶</a>
</p>
