<p align="left">
 <a href="02_17.md">◀ Back: The unknown Type.</a>
</p>

---

# The never Type.

El último tipo de datos de TypeScript que vamos a ver en este capítulo es el que se conoce como **never**. Anterioremente [hemos visto](./02_14.md) como todas aquellas funciones que no van a retornar un valor el tipo de datos que se le asigna como valor de retorno es void:

```ts
function printResult(num: number): void {
  console.log('Result: ' + num)
}
```

Lo que tenemos que entender es que el tipo de datos never es el tipo de datos que retornarán todas aquellas funciones que retornan void. Esto que suena extraño se entiende mucho mejor si desarrollamos un ejemplo. Supongamos que vamos a definir una función la cual recibe como parámetro un mensaje (string) y un código de error (number) y cuya responsabilidad será lanzar un error dentro de la ejecución del mismo. El código sería algo como lo siguiente:

```ts
function generateError(message: string, code: number) {
  throw { error, errorCode: code }
}
```

---
**Nota:** el código anterior puede resultar extraño para algunos desarrolladores que no conozcan JavaScript en profundidad pero cabe recordar que en el lenguaje la claúsula `throw` se puede acompañar de cualquier objeto que no tiene por qué ser siempre una instancia del objeto `Error` del lenguaje (aunque sí que es lo más frecuente) y es en esto en lo que nos hemos basado en el ejemplo anterior.

---

El siguiente paso en el desarrollo de nuestro ejemplo va a consistir en invocar a nuestra nueva función `generateError` a la que le pasamos los parámetros que necesita para ser ejecutada:

```ts
function generateError(message: string, code: number) {
  throw { message, errorCode: code }
}

generateError('An error occurred!', 500)
```

Si guardamos nuestro trabajo, lo compilamos y lo ejecutamos en la consola del sistema obtendremos algo como lo siguiente:

```bash
$ tsc app.ts
$ node app.js
  /home/courses/typescript/app.js:2
      throw { message: message, errorCode: code };
      ^
  { message: 'An error occurred!', errorCode: 500 }
```

---
**Nota:** el hecho de tener una función como `generateError` puede parecer a priori extraño pero es bastante habitual que en las aplicaciones medianamente grandes dispongamos de una serie de funciones de utilidad que sirvan para realizar acciones como la que realiza esta función, es decir, que se lancen errores en función de los valores de los parámetros de entrada.

---

La pregunga que nos tenemos que hacer ante una función como la anterior es ¿realmente está retornando el tipo de datos void como sucede con una función de las que hemos visto hasta ahora? TypeScript establecerá por nosotros que el tipo de datos de `generateError` es void pero, para ser totalmente honestos, como dentro de la misma se está lanzando un error nos encontramos con que el tipo de datos que realmente estará retornando es never ya que nunca produce un valor de retorno.

Esto lo podemos comprobar fácilmente con el siguiente código:

```ts
function generateError(message: string, code: number) {
  throw { message, errorCode: code }
}

const result = generateError('An error occurred!', 500)
console.log(result)
```

Si volvemos a guardar nuestro trabajo, lo compilamos y lo volvemos a ejecutar en la consola del sistema volvemos a ver el mismo mensaje de error que en la última ejecución derivado de que se lanza el error y la ejecución del programa finaliza inmediatamente:

```bash
$ tsc app.ts
$ node app.js
  /home/courses/typescript/app.js:2
      throw { message: message, errorCode: code };
      ^
  { message: 'An error occurred!', errorCode: 500 }
```

En otras palabras, en la salida anterior por la consola en ningún punto estamos viendo el valor `undefined` asociado al hecho que se intenta imprimir un valor que es retornado por una función cuyo tipo de datos de retorno es void.

---
**Nota:** evidentemente la llamada a la función `generateError` puede estar encapsulada en un bloque `try-catch` lo que significaría que el error no va a provocar que el código deje de funcionar.

---

Por lo tanto, como la función `generateError` siempre va a lanzar un error con una sentencia `throw` el tipo de datos que ha de tener asignado no va a ser `void` como pensábamos hasta ahora (y que le asignará por defecto TypeScript) sino técnicamente ha de ser `never`. Por lo tanto redefinimos la función de la siguiente manera:

```ts
function generateError(message: string, code: number): never {
  throw { message, errorCode: code }
}
```

> Aunque el uso de never no es obligatorio al indicar que una función retorna este tipo de datos estaremos siendo muy explícitos a la hora de afirmar que la función en cuestión nunca va a finalizar lo que ayudará a otros desarrolladores a entender mejor qué es lo que pretendemos hacer en ella.

Otro ejemplo de una función que nunca va a retornar un valor es aquella que dentro de la misma se está llevando a cabo un bucle infinito (por ejemplo una función que se dedica a ejecutar el bucle principal de un juego) como se puede ver en el siguiente caso:

```ts
function infiniteLoop(): never {
  while (true) {
    // ...
  }
}
```

---

<p align="right">
 <a href="02_19.md">Next: Wrap Up ▶</a>
</p>
